Workbook
Name NAMA_RS: '01_Profil_RS'!$C$6
Name ALAMAT: '01_Profil_RS'!$C$7
Name TAHUN: '01_Profil_RS'!$C$8
Name JENIS_RS: '01_Profil_RS'!$C$9
Name KELAS_RS: '01_Profil_RS'!$C$10
Name KEPEMILIKAN: '01_Profil_RS'!$C$11
Name REGIONAL: '01_Profil_RS'!$C$12
Name HARI_TAHUN: '01_Profil_RS'!$C$14
Name HARI_LIBUR: '01_Profil_RS'!$C$15
Name HARI_KERJA: '01_Profil_RS'!$C$16
Name JAM_KERJA_DEF: '01_Profil_RS'!$C$17
Name MENIT_HILANG_DEF: '01_Profil_RS'!$C$18
Name LUAS_GEDUNG: '01_Profil_RS'!$C$20
Name NILAI_GEDUNG: '01_Profil_RS'!$C$21
Name UMUR_GEDUNG: '01_Profil_RS'!$C$22
Name SISA_GEDUNG: '01_Profil_RS'!$C$23
Name SUSUT_GEDUNG: '01_Profil_RS'!$C$24
Name RASIO_BERSIH: '01_Profil_RS'!$C$25
Name METODE_M2: '01_Profil_RS'!$C$26
Name LUAS_BERSIH_INV: '01_Profil_RS'!$C$27
Name TARIF_M2: '01_Profil_RS'!$C$28
Name KAP_PRAKTIS: '01_Profil_RS'!$C$30
Name LOS: '01_Profil_RS'!$C$31
Name METODE_OH: '01_Profil_RS'!$C$33
Name KWH_TAHUN: '01_Profil_RS'!$C$35
Name TARIF_KWH: '01_Profil_RS'!$C$36
Name TOTAL_LISTRIK: '01_Profil_RS'!$C$37
Name SUMBER_BOBOT: '01_Profil_RS'!$C$38
Name UNIT_ACUAN: '01_Profil_RS'!$C$39
Name VERSI_TEMPLATE: '01_Profil_RS'!$C$41

Sheet 00_Petunjuk
B2: UnitCost by Medisin · Template Tahap 1 – Pengumpulan Data
B3: Unit cost TDABC + step down (KMK HK.01.07/MENKES/346/2025) · versi isian
B5: Tujuan tahap 1 | C5: Mengumpulkan data dasar rumah sakit yang lengkap dan tervalidasi. Perhitungan CCR, alokasi step down, unit cost, dan tarif dilakukan di aplikasi UnitCost pada Tahap 2 bersama pendamping.
B6: Isi file ini | C6: 8 kelompok data: (1) identitas & parameter: 01, 02 · (2) SDM & gaji: 13 · (3) ruangan & luas: 14, 07 · (4) aset/alat: 15, 03 · (5) obat & BMHP: 18 · (6) tindakan & volume: 19, 12 · (7) biaya tidak langsung: 10 · (8) aktivitas & waktu: 20, 21, 22.
B7: Arti warna kolom | C7: Lihat kotak warna di bawah. Baris ke-3 setiap sheet juga menuliskan jenis kolomnya (WAJIB DIISI / PERIKSA / OPSIONAL / DIATUR PENDAMPING / OTOMATIS).
B8: Cara mengisi | C8: 1) Isi sheet berurutan 01 → 22. 2) Fokus pada kolom KUNING (wajib diisi); kolom biru diperiksa, kolom putih opsional, kolom abu-abu jangan diubah. 3) Satu baris = satu data; jangan menggabung sel. 4) Angka tanpa titik ribuan atau satuan bila memungkinkan.
B9: Kamus data | C9: Sheet 00b_Kamus_Data: arti setiap kolom, contoh isian, dan sumber datanya.
B10: Checklist | C10: Sheet 00c_Checklist: penanggung jawab tiap sheet, target, status, dan jumlah baris terisi. Dipakai saat sesi pendampingan.
B11: Referensi bawaan | C11: Sheet 02, 03, 07, 10, dan 12 sudah berisi daftar standar. Sesuaikan dengan rumah sakit Anda. Kolom kode pusat biaya biarkan apa adanya; pengaturan step down, margin, dan listrik dilakukan bersama pendamping di Tahap 2–3.
B12: Cek mandiri | C12: Sheet 23_Cek_Data menghitung baris terisi, kode ganda, dan rujukan yang tidak ditemukan. Usahakan semua berstatus OK sebelum sesi berikutnya.
B13: Kerahasiaan | C13: Data ini milik rumah sakit Anda. File diunggah ke akun UnitCost rumah sakit Anda sendiri dan tidak dibagikan ke peserta lain.
B14: Tahap berikutnya | C14: Tahap 2 Unit cost → Tahap 3 Tarif & clinical pathway → Tahap 4 Analisis INA-CBG/iDRG. Setiap tahap dibuka di aplikasi setelah sesi pendampingan.
B16: ARTI WARNA
B17: WAJIB DIISI | C17: Data rumah sakit yang harus diisi peserta. Target utama Tahap 1.
B18: PERIKSA / SESUAIKAN | C18: Sudah berisi nilai/daftar standar. Periksa dan sesuaikan dengan kondisi RS.
B19: OPSIONAL | C19: Boleh dikosongkan; isi bila datanya ada (keterangan, sumber data).
B20: DIATUR PENDAMPING | C20: Jangan diubah. Diatur bersama pendamping di Tahap 2.
B21: OTOMATIS | C21: Terisi otomatis dari sheet lain. Jangan diketik.

Sheet 00b_Kamus_Data
A1: Sheet | B1: Kolom | C1: Jenis kolom | D1: Arti / cara mengisi | E1: Sumber data
A2: 01_Profil_RS | B2: Identitas RS, hari kerja, data gedung, listrik setahun | E2: SK, PBG/IMB, laporan aset gedung, tagihan PLN 12 bulan
A3: 02_Pola_Layanan | B3: Jam & hari operasional tiap pola layanan | E3: Jadwal pelayanan
B4: Pola Layanan | C4: Periksa / sesuaikan
B5: Jam Operasional / Hari | C5: Periksa / sesuaikan | D5: Jam kerja per hari sesuai jadwal.
B6: Hari Operasional / Tahun | C6: Periksa / sesuaikan
B7: Keterangan | C7: Periksa / sesuaikan
A8: 03_Kategori_Aset | B8: Kategori aset & umur ekonomis | E8: Kebijakan akuntansi aset
B9: Kode Kategori | C9: Periksa / sesuaikan
B10: Nama Kategori Aset | C10: Periksa / sesuaikan
B11: Jenis | C11: Periksa / sesuaikan
B12: Umur Ekonomis (tahun) | C12: Periksa / sesuaikan
A13: 07_Unit | B13: Daftar unit/instalasi & pusat biayanya | E13: Struktur organisasi
B14: Kode Unit | C14: Periksa / sesuaikan
B15: Nama Unit | C15: Periksa / sesuaikan
B16: Jenis Unit | C16: Periksa / sesuaikan
B17: Kode Pusat Biaya | C17: Diatur pendamping
A18: 10_Biaya_Tdk_Langsung | B18: Biaya tidak langsung setahun & penanggungnya | E18: Buku besar / laporan realisasi biaya
B19: Kode | C19: Periksa / sesuaikan
B20: Uraian Biaya Tidak Langsung | C20: Periksa / sesuaikan
B21: Biaya 1 Tahun (Rp) | C21: Wajib diisi | D21: Biaya 1 tahun dalam rupiah.
B22: Kode PB Penanggung | C22: Diatur pendamping
B23: Kategori | C23: Periksa / sesuaikan
B24: Sumber Data | C24: Opsional
A25: 12_Kelompok_Tindakan | B25: Kelompok tindakan & pusat biaya finalnya | E25: Buku tarif RS
B26: Kelompok Tindakan | C26: Periksa / sesuaikan
B27: Kode PB Final | C27: Diatur pendamping
B28: Pembagi | C28: Diatur pendamping
B29: Keterangan | C29: Opsional
A30: 13_Profesi_SDM | B30: Profesi, penghasilan setahun, jam kerja, jumlah orang | E30: Daftar gaji + insentif + tunjangan 12 bulan
B31: Kode Profesi | C31: Wajib diisi
B32: Profesi / Jabatan | C32: Wajib diisi
B33: Penghasilan 1 Tahun (Rp) | C33: Wajib diisi | D33: Total penghasilan 1 orang setahun: gaji + tunjangan + insentif/jasa pelayanan + BPJS yang dibayar RS.
B34: Jam Kerja / Hari | C34: Wajib diisi | D34: Jam kerja per hari sesuai jadwal.
B35: Menit Hilang / Hari | C35: Wajib diisi | D35: Menit tidak produktif per hari (istirahat, administrasi, dll.).
B36: Jumlah SDM | C36: Wajib diisi | D36: Jumlah orang / unit.
B37: Unit Pengguna Utama | C37: Opsional
B38: Keterangan | C38: Opsional
A39: 14_Ruang | B39: Ruangan, luas, jumlah, pola layanan | E39: Denah, inventaris ruang
B40: Kode Ruang | C40: Wajib diisi
...

Sheet 00c_Checklist
A1: No | B1: Sheet | C1: Isi | D1: Penanggung jawab | E1: Target selesai | F1: Baris terisi | G1: Status | H1: Catatan pendamping
A2: 1 | B2: 01_Profil_RS | C2: Identitas RS, hari kerja, data gedung, listrik setahun | D2: Direksi / Keuangan / IPSRS | F2: =COUNTA('01_Profil_RS'!C5:C41) | G2: Belum
A3: 2 | B3: 02_Pola_Layanan | C3: Jam & hari operasional tiap pola layanan | D3: Pelayanan medis | F3: =COUNTA('02_Pola_Layanan'!A5:A6000) | G3: Belum
A4: 3 | B4: 03_Kategori_Aset | C4: Kategori aset & umur ekonomis | D4: Keuangan / Aset | F4: =COUNTA('03_Kategori_Aset'!A5:A6000) | G4: Belum
A5: 4 | B5: 07_Unit | C5: Daftar unit/instalasi & pusat biayanya | D5: Perencanaan / Keuangan | F5: =COUNTA('07_Unit'!A5:A6000) | G5: Belum
A6: 5 | B6: 10_Biaya_Tdk_Langsung | C6: Biaya tidak langsung setahun & penanggungnya | D6: Keuangan | F6: =COUNTA('10_Biaya_Tdk_Langsung'!A5:A6000) | G6: Belum
A7: 6 | B7: 12_Kelompok_Tindakan | C7: Kelompok tindakan & pusat biaya finalnya | D7: Keuangan / Pelayanan | F7: =COUNTA('12_Kelompok_Tindakan'!A5:A6000) | G7: Belum
A8: 7 | B8: 13_Profesi_SDM | C8: Profesi, penghasilan setahun, jam kerja, jumlah orang | D8: SDM / Keuangan | F8: =COUNTA('13_Profesi_SDM'!A5:A6000) | G8: Belum
A9: 8 | B9: 14_Ruang | C9: Ruangan, luas, jumlah, pola layanan | D9: IPSRS / Sarpras | F9: =COUNTA('14_Ruang'!A5:A6000) | G9: Belum
A10: 9 | B10: 15_Aset_Alat | C10: Alat medis & non-medis per ruangan beserta harga | D10: Aset / IPSRS | F10: =COUNTA('15_Aset_Alat'!A5:A6000) | G10: Belum
A11: 10 | B11: 18_Obat_BMHP | C11: Master obat & BMHP beserta harga satuan | D11: Farmasi / Logistik | F11: =COUNTA('18_Obat_BMHP'!A5:A6000) | G11: Belum
A12: 11 | B12: 19_Tindakan | C12: Buku tarif eksisting + volume setahun | D12: Keuangan / Rekam medik | F12: =COUNTA('19_Tindakan'!A5:A6000) | G12: Belum
A13: 12 | B13: 20_Aktivitas_SDM | C13: Rincian waktu SDM per tindakan (time study) | D13: KSM / Kepala ruang | F13: =COUNTA('20_Aktivitas_SDM'!A5:A6000) | G13: Belum
A14: 13 | B14: 21_Okupansi_Ruang | C14: Lama pemakaian ruang per tindakan | D14: Kepala ruang | F14: =COUNTA('21_Okupansi_Ruang'!A5:A6000) | G14: Belum
A15: 14 | B15: 22_Pemakaian_BMHP | C15: Obat & BMHP yang dipakai per tindakan | D15: Farmasi + kepala ruang | F15: =COUNTA('22_Pemakaian_BMHP'!A5:A6000) | G15: Belum

Sheet 01_Profil_RS
A1: 01 · Profil RS & Parameter Perhitungan
A2: Isi kolom Nilai. Kuning = WAJIB diisi data RS · Biru muda = periksa nilai bawaan · Abu-abu = diatur pendamping / dihitung aplikasi. Kolom "Kode" dipakai aplikasi – JANGAN diubah.
A4: Kode | B4: Parameter | C4: Nilai | D4: Satuan | E4: Keterangan / cara mengisi
A5: A. IDENTITAS
A6: NAMA_RS | B6: Nama rumah sakit | D6: teks | E6: Tampil di kepala setiap halaman dan laporan.
A7: ALAMAT | B7: Alamat rumah sakit | D7: teks | E7: Boleh kosong.
A8: TAHUN | B8: Tahun perhitungan | C8: 2026 | D8: tahun | E8: Tahun data biaya yang dipakai.
A9: JENIS_RS | B9: Jenis rumah sakit | C9: RS UMUM | D9: teks | E9: RS UMUM atau RS KHUSUS.
A10: KELAS_RS | B10: Kelas rumah sakit | D10: teks | E10: Tipe A / Tipe B / Tipe C / Tipe D.
A11: KEPEMILIKAN | B11: Kepemilikan | D11: teks | E11: Mis. RS Pemerintah / RS Swasta.
A12: REGIONAL | B12: Regional | D12: teks | E12: Regional tarif sesuai KMK.
A13: B. KAPASITAS WAKTU SDM
A14: HARI_TAHUN | B14: Jumlah hari dalam 1 tahun | C14: 365 | D14: hari | E14: Kalender: 365 atau 366.
A15: HARI_LIBUR | B15: Jumlah hari libur dalam 1 tahun | C15: 118 | D15: hari | E15: Sabtu–Minggu + libur nasional/cuti bersama.
A16: HARI_KERJA | B16: Hari kerja efektif dalam 1 tahun | C16: =HARI_TAHUN-HARI_LIBUR | D16: hari | E16: OTOMATIS = hari dalam setahun − hari libur.
A17: JAM_KERJA_DEF | B17: Jam kerja SDM per hari (nilai awal) | C17: 8 | D17: jam | E17: Nilai awal untuk profesi baru yang ditambah langsung di aplikasi.
A18: MENIT_HILANG_DEF | B18: Menit hilang per hari (nilai awal) | C18: 60 | D18: menit | E18: Istirahat, rapat, dll. Nilai awal untuk profesi baru.
A19: C. BANGUNAN
A20: LUAS_GEDUNG | B20: Total luas lantai gedung (PBG) | D20: m² | E20: Luas kotor sesuai izin bangunan.
A21: NILAI_GEDUNG | B21: Nilai perolehan gedung | D21: Rp | E21: Nilai buku/perolehan gedung.
A22: UMUR_GEDUNG | B22: Umur ekonomis gedung | C22: 20 | D22: tahun | E22: Sesuai kebijakan akuntansi RS.
A23: SISA_GEDUNG | B23: Nilai sisa gedung | C23: 0 | D23: Rp | E23: Umumnya 0 (garis lurus).
A24: SUSUT_GEDUNG | B24: Penyusutan gedung per tahun | C24: (dihitung di aplikasi) | D24: Rp/th | E24: OTOMATIS (garis lurus).
A25: RASIO_BERSIH | B25: Rasio luas bersih cadangan | C25: 0.8 | D25: pecahan | E25: Luas bersih ÷ luas kotor, mis. 0,8. Dipakai metode 2.
A26: METODE_M2 | B26: Metode tarif gedung per m² (1 atau 2) | C26: 2 | D26: 1 / 2 | E26: 1 = ÷ luas bersih inventaris ruang; 2 = ÷ (rasio × luas PBG).
A27: LUAS_BERSIH_INV | B27: Total luas bersih inventaris ruang | C27: =SUM('14_Ruang'!$M$5:$M$405) | D27: m² | E27: OTOMATIS = jumlah luas di sheet 14_Ruang.
A28: TARIF_M2 | B28: Tarif penyusutan gedung per m² per tahun | C28: (dihitung di aplikasi) | D28: Rp/m² | E28: OTOMATIS sesuai metode yang dipilih.
A29: D. KAPASITAS PRAKTIS & KASUS ACUAN
A30: KAP_PRAKTIS | B30: Kapasitas praktis sarana | C30: 0.85 | D30: pecahan | E30: Lazim 0,80–0,85 (dikurangi persiapan, pembersihan, downtime).
A31: LOS | B31: Lama rawat (LOS) kasus acuan | D31: hari | E31: Membagi overhead rawat inap per hari dan volume per episode.
A32: E. METODE OVERHEAD
A33: METODE_OH | B33: Metode biaya tidak langsung per kegiatan (1, 2, atau 3) | C33: 3 | D33: 1 / 2 / 3 | E33: 1 = proporsi pendapatan; 2 = AIC ÷ volume unit; 3 = AIC × menit ruang (disarankan).
A34: F. LISTRIK
A35: KWH_TAHUN | B35: Total pemakaian listrik RS setahun | D35: kWh | E35: Dari tagihan PLN/Genset setahun.
A36: TARIF_KWH | B36: Tarif listrik per kWh | D36: Rp/kWh | E36: Rata-rata tarif per kWh.
A37: TOTAL_LISTRIK | B37: Total biaya listrik setahun | C37: (dihitung di aplikasi) | D37: Rp | E37: OTOMATIS = kWh × tarif.
A38: SUMBER_BOBOT | B38: Sumber bobot listrik (1 atau 2) | C38: 2 | D38: 1 / 2 | E38: 1 = asumsi (sheet 17); 2 = hasil kalkulator dari beban listrik (sheet 16).
A39: UNIT_ACUAN | B39: Unit acuan kalkulator bobot (Kode Unit) | C39: U01 | D39: kode | E39: Kode unit dari sheet 07 yang bobotnya = 1 pada kalkulator.
A40: G. VERSI
A41: VERSI_TEMPLATE | B41: Versi template | C41: UC-TDABC-3.0 | D41: teks | E41: JANGAN DIUBAH. Dipakai aplikasi untuk mengenali template.

Sheet 02_Pola_Layanan
A1: 02 · Pola Layanan (jam & hari operasional sarana)
A2: Menentukan kapasitas teoretis ruangan. Setiap ruangan di sheet 14 memilih satu pola. Kosongkan "Hari Operasional" bila ingin memakai hari kerja efektif.
A3: PERIKSA / SESUAIKAN | B3: PERIKSA / SESUAIKAN | C3: PERIKSA / SESUAIKAN | D3: PERIKSA / SESUAIKAN
A4: Pola Layanan | B4: Jam Operasional / Hari | C4: Hari Operasional / Tahun | D4: Keterangan
A5: 24 jam | B5: 24 | C5: 365 | D5: IGD, rawat inap, ICU, VK, OK, lab & radiologi (layanan 24 jam)
A6: Jam kerja poli | B6: 7 | C6: 290 | D6: Poliklinik & layanan rawat jalan (±6 hari/minggu dikurangi libur)
A7: Elektif | B7: 8 | C7: 290 | D7: Tindakan terjadwal: endoskopi, cath lab
A8: HD 2 shift | B8: 10 | C8: 312 | D8: Hemodialisa 2 shift, 6 hari/minggu
A9: 12 jam | B9: 12 | C9: 365 | D9: Gizi, laundry, CSSD, kantin
A10: Jam kerja kantor | B10: 8 | D10: Manajemen & penunjang umum (5 hari/minggu)

Sheet 03_Kategori_Aset
A1: 03 · Kategori Aset & Umur Ekonomis
A2: Satu tabel kategori alat. Umur ekonomis dan jenis (Medis / Non-Medis) diambil otomatis oleh sheet 15 berdasarkan kode kategori.
A3: PERIKSA / SESUAIKAN | B3: PERIKSA / SESUAIKAN | C3: PERIKSA / SESUAIKAN | D3: PERIKSA / SESUAIKAN
A4: Kode Kategori | B4: Nama Kategori Aset | C4: Jenis | D4: Umur Ekonomis (tahun)
A5: MB | B5: Alat Medis Berat (imaging, cath lab, sterilisator besar) | C5: Medis | D5: 10
A6: ME | B6: Alat Medis Elektromedik | C6: Medis | D6: 5
A7: MN | B7: Alat Medis Non-Elektrik & Instrumen | C7: Medis | D7: 5
A8: NB | B8: Mesin & Peralatan Berat Non-Medis (genset, laundry) | C8: Non-Medis | D8: 10
A9: NE | B9: Peralatan Elektronik & Rumah Tangga (AC, TV, kulkas, dapur) | C9: Non-Medis | D9: 5
A10: NI | B10: Komputer & Perangkat IT | C10: Non-Medis | D10: 4
A11: NM | B11: Mebel & Perabot | C11: Non-Medis | D11: 5

Sheet 07_Unit
A1: 07 · Unit (kelompok ruangan di bawah pusat biaya)
A2: Unit dipakai untuk rekap sarana, bobot listrik, dan beban listrik. Setiap unit milik tepat satu pusat biaya (sheet 08).
A3: PERIKSA / SESUAIKAN | B3: PERIKSA / SESUAIKAN | C3: PERIKSA / SESUAIKAN | D3: DIATUR PENDAMPING | E3: OTOMATIS
A4: Kode Unit | B4: Nama Unit | C4: Jenis Unit | D4: Kode Pusat Biaya | E4: Nama Pusat Biaya
A5: U01 | B5: Rawat Jalan | C5: Produksi | D5: PB10 | E5: =IF(D5="","",IFERROR(INDEX('08_Pusat_Biaya'!$C:$C,MATCH(D5,'08_Pusat_Biaya'!$A:$A,0)),"⚠ kode tidak ditemukan"))
A6: U02 | B6: Poli Gigi | C6: Produksi | D6: PB18 | E6: =IF(D6="","",IFERROR(INDEX('08_Pusat_Biaya'!$C:$C,MATCH(D6,'08_Pusat_Biaya'!$A:$A,0)),"⚠ kode tidak ditemukan"))
A7: U03 | B7: IGD | C7: Produksi | D7: PB12 | E7: =IF(D7="","",IFERROR(INDEX('08_Pusat_Biaya'!$C:$C,MATCH(D7,'08_Pusat_Biaya'!$A:$A,0)),"⚠ kode tidak ditemukan"))
A8: U04 | B8: Rawat Inap | C8: Produksi | D8: PB11 | E8: =IF(D8="","",IFERROR(INDEX('08_Pusat_Biaya'!$C:$C,MATCH(D8,'08_Pusat_Biaya'!$A:$A,0)),"⚠ kode tidak ditemukan"))
A9: U05 | B9: Perinatologi | C9: Produksi | D9: PB11 | E9: =IF(D9="","",IFERROR(INDEX('08_Pusat_Biaya'!$C:$C,MATCH(D9,'08_Pusat_Biaya'!$A:$A,0)),"⚠ kode tidak ditemukan"))
A10: U06 | B10: Kebidanan (VK) | C10: Produksi | D10: PB16 | E10: =IF(D10="","",IFERROR(INDEX('08_Pusat_Biaya'!$C:$C,MATCH(D10,'08_Pusat_Biaya'!$A:$A,0)),"⚠ kode tidak ditemukan"))
A11: U07 | B11: Kamar Operasi | C11: Produksi | D11: PB15 | E11: =IF(D11="","",IFERROR(INDEX('08_Pusat_Biaya'!$C:$C,MATCH(D11,'08_Pusat_Biaya'!$A:$A,0)),"⚠ kode tidak ditemukan"))
A12: U08 | B12: Laboratorium | C12: Produksi | D12: PB13 | E12: =IF(D12="","",IFERROR(INDEX('08_Pusat_Biaya'!$C:$C,MATCH(D12,'08_Pusat_Biaya'!$A:$A,0)),"⚠ kode tidak ditemukan"))
A13: U09 | B13: Radiologi | C13: Produksi | D13: PB14 | E13: =IF(D13="","",IFERROR(INDEX('08_Pusat_Biaya'!$C:$C,MATCH(D13,'08_Pusat_Biaya'!$A:$A,0)),"⚠ kode tidak ditemukan"))
A14: U10 | B14: Rehabilitasi Medik | C14: Produksi | D14: PB17 | E14: =IF(D14="","",IFERROR(INDEX('08_Pusat_Biaya'!$C:$C,MATCH(D14,'08_Pusat_Biaya'!$A:$A,0)),"⚠ kode tidak ditemukan"))
A15: U11 | B15: Farmasi | C15: Penunjang Medis | D15: PB08 | E15: =IF(D15="","",IFERROR(INDEX('08_Pusat_Biaya'!$C:$C,MATCH(D15,'08_Pusat_Biaya'!$A:$A,0)),"⚠ kode tidak ditemukan"))
A16: U12 | B16: CSSD | C16: Penunjang Medis | D16: PB09 | E16: =IF(D16="","",IFERROR(INDEX('08_Pusat_Biaya'!$C:$C,MATCH(D16,'08_Pusat_Biaya'!$A:$A,0)),"⚠ kode tidak ditemukan"))
... A23: U19 | B23: Umum | C23: Penunjang Umum | D23: PB02 | E23: =IF(D23="","",IFERROR(INDEX('08_Pusat_Biaya'!$C:$C,MATCH(D23,'08_Pusat_Biaya'!$A:$A,0)),"⚠ kode tidak ditemukan"))
E24: =IF(D24="","",IFERROR(INDEX('08_Pusat_Biaya'!$C:$C,MATCH(D24,'08_Pusat_Biaya'!$A:$A,0)),"⚠ kode tidak ditemukan"))
E25: =IF(D25="","",IFERROR(INDEX('08_Pusat_Biaya'!$C:$C,MATCH(D25,'08_Pusat_Biaya'!$A:$A,0)),"⚠ kode tidak ditemukan"))
E26: =IF(D26="","",IFERROR(INDEX('08_Pusat_Biaya'!$C:$C,MATCH(D26,'08_Pusat_Biaya'!$A:$A,0)),"⚠ kode tidak ditemukan"))
E27: =IF(D27="","",IFERROR(INDEX('08_Pusat_Biaya'!$C:$C,MATCH(D27,'08_Pusat_Biaya'!$A:$A,0)),"⚠ kode tidak ditemukan"))
E28: =IF(D28="","",IFERROR(INDEX('08_Pusat_Biaya'!$C:$C,MATCH(D28,'08_Pusat_Biaya'!$A:$A,0)),"⚠ kode tidak ditemukan"))
E29: =IF(D29="","",IFERROR(INDEX('08_Pusat_Biaya'!$C:$C,MATCH(D29,'08_Pusat_Biaya'!$A:$A,0)),"⚠ kode tidak ditemukan"))
E30: =IF(D30="","",IFERROR(INDEX('08_Pusat_Biaya'!$C:$C,MATCH(D30,'08_Pusat_Biaya'!$A:$A,0)),"⚠ kode tidak ditemukan"))
E31: =IF(D31="","",IFERROR(INDEX('08_Pusat_Biaya'!$C:$C,MATCH(D31,'08_Pusat_Biaya'!$A:$A,0)),"⚠ kode tidak ditemukan"))
E32: =IF(D32="","",IFERROR(INDEX('08_Pusat_Biaya'!$C:$C,MATCH(D32,'08_Pusat_Biaya'!$A:$A,0)),"⚠ kode tidak ditemukan"))
E33: =IF(D33="","",IFERROR(INDEX('08_Pusat_Biaya'!$C:$C,MATCH(D33,'08_Pusat_Biaya'!$A:$A,0)),"⚠ kode tidak ditemukan"))
E34: =IF(D34="","",IFERROR(INDEX('08_Pusat_Biaya'!$C:$C,MATCH(D34,'08_Pusat_Biaya'!$A:$A,0)),"⚠ kode tidak ditemukan"))
E35: =IF(D35="","",IFERROR(INDEX('08_Pusat_Biaya'!$C:$C,MATCH(D35,'08_Pusat_Biaya'!$A:$A,0)),"⚠ kode tidak ditemukan"))
... E84: =IF(D84="","",IFERROR(INDEX('08_Pusat_Biaya'!$C:$C,MATCH(D84,'08_Pusat_Biaya'!$A:$A,0)),"⚠ kode tidak ditemukan"))

Sheet 08_Pusat_Biaya
A1: 08 · Pusat Biaya (Cost Center) – urutan step-down
A2: Satu baris per pusat biaya. Urutan Step-Down menentukan siapa membagi biaya lebih dulu: Overhead → Intermediate → Final. Kolom Final-saja (kelompok volume, satuan, pendapatan) boleh kosong untuk Overhead/Intermediate.
A3: ISI | B3: ISI | C3: ISI | D3: ISI | E3: ISI | F3: ISI | G3: ISI | H3: ISI | I3: ISI | J3: ISI | K3: ISI | L3: OTOMATIS | M3: OTOMATIS
A4: Kode PB | B4: Urutan Step-Down | C4: Nama Pusat Biaya | D4: Jenis Pusat Biaya | E4: Dasar Alokasi (sebagai pengirim) | F4: Biaya Langsung Lain (Rp/tahun) | G4: Kelompok Volume (khusus Final) | H4: Volume dibagi LOS? (Ya/Tidak) | I4: Satuan Kegiatan | J4: Pendapatan 1 Tahun (Rp) | K4: Keterangan | L4: Volume Kegiatan 1 Tahun (dihitung di aplikasi) | M4: Total Luas (m²)
A5: PB01 | B5: 1 | C5: Manajemen & Administrasi | D5: Overhead | E5: Jumlah pegawai | K5: Direksi, keuangan, SDM, IT, mutu. Dibagi menurut jumlah pegawai tiap pusat biaya. | M5: =IF(A5="","",SUMIF('14_Ruang'!$L:$L,A5,'14_Ruang'!$M:$M))
A6: PB02 | B6: 2 | C6: Umum (Kebersihan, Keamanan, Gudang) | D6: Overhead | E6: Luas lantai | K6: Kebersihan, keamanan, sopir/ambulans, gudang. Dibagi menurut luas lantai. | M6: =IF(A6="","",SUMIF('14_Ruang'!$L:$L,A6,'14_Ruang'!$M:$M))
A7: PB03 | B7: 3 | C7: IPSRS (Pemeliharaan Sarana) | D7: Overhead | E7: Luas lantai | K7: Pemeliharaan gedung & alat. Dibagi menurut luas lantai. | M7: =IF(A7="","",SUMIF('14_Ruang'!$L:$L,A7,'14_Ruang'!$M:$M))
A8: PB04 | B8: 4 | C8: Rekam Medis | D8: Overhead | E8: Total Hari Rawat dan Kunjungan | K8: Pelayanan RM & koding. Dibagi menurut hari rawat + kunjungan (beban berkas). | M8: =IF(A8="","",SUMIF('14_Ruang'!$L:$L,A8,'14_Ruang'!$M:$M))
A9: PB05 | B9: 5 | C9: Laundry | D9: Overhead | E9: Jumlah Kg cucian | K9: Linen & pakaian kerja. Dibagi menurut kg cucian. | M9: =IF(A9="","",SUMIF('14_Ruang'!$L:$L,A9,'14_Ruang'!$M:$M))
A10: PB06 | B10: 6 | C10: Gizi | D10: Overhead | E10: Jumlah Hari rawat | K10: Makanan pasien rawat inap. Dibagi menurut hari rawat. | M10: =IF(A10="","",SUMIF('14_Ruang'!$L:$L,A10,'14_Ruang'!$M:$M))
A11: PB07 | B11: 7 | C11: Pemulasaran Jenazah | D11: Overhead | E11: Jumlah pasien rawat inap | K11: Kamar jenazah. Dibagi menurut jumlah pasien rawat inap. | M11: =IF(A11="","",SUMIF('14_Ruang'!$L:$L,A11,'14_Ruang'!$M:$M))
A12: PB08 | B12: 8 | C12: Farmasi | D12: Intermediate | E12: Jumlah resep | K12: Depo farmasi (gaji apoteker/TTK dihitung lewat CCR SDM). Dibagi menurut jumlah resep. | M12: =IF(A12="","",SUMIF('14_Ruang'!$L:$L,A12,'14_Ruang'!$M:$M))
A13: PB09 | B13: 9 | C13: CSSD | D13: Intermediate | E13: Jumlah tindakan | K13: Sterilisasi alat. Dibagi menurut jumlah tindakan yang memakai set steril. | M13: =IF(A13="","",SUMIF('14_Ruang'!$L:$L,A13,'14_Ruang'!$M:$M))
A14: PB10 | B14: 10 | C14: Rawat Jalan | D14: Final Rawat Jalan | G14: Konsultasi Rawat Jalan | H14: Tidak | I14: kunjungan | K14: Poliklinik umum & spesialis dasar. | M14: =IF(A14="","",SUMIF('14_Ruang'!$L:$L,A14,'14_Ruang'!$M:$M))
A15: PB11 | B15: 11 | C15: Rawat Inap | D15: Final Rawat Inap | G15: Rawat Inap – Kamar Perawatan | H15: Ya | I15: episode | K15: Seluruh bangsal rawat inap, termasuk ruang nifas dan perinatologi. | M15: =IF(A15="","",SUMIF('14_Ruang'!$L:$L,A15,'14_Ruang'!$M:$M))
A16: PB12 | B16: 12 | C16: IGD | D16: Final Rawat Jalan | G16: IGD | H16: Tidak | I16: kunjungan | K16: Instalasi Gawat Darurat 24 jam. | M16: =IF(A16="","",SUMIF('14_Ruang'!$L:$L,A16,'14_Ruang'!$M:$M))
A17: PB13 | B17: 13 | C17: Laboratorium | D17: Final Penunjang / Tindakan | G17: Patologi Klinik | H17: Tidak | I17: pemeriksaan | K17: Laboratorium klinik 24 jam. | M17: =IF(A17="","",SUMIF('14_Ruang'!$L:$L,A17,'14_Ruang'!$M:$M))
A18: PB14 | B18: 14 | C18: Radiologi | D18: Final Penunjang / Tindakan | G18: Radiologi | H18: Tidak | I18: pemeriksaan | K18: Rontgen digital dan USG. | M18: =IF(A18="","",SUMIF('14_Ruang'!$L:$L,A18,'14_Ruang'!$M:$M))
A19: PB15 | B19: 15 | C19: Kamar Bedah | D19: Final Penunjang / Tindakan | G19: Kamar Bedah | H19: Tidak | I19: tindakan | K19: Bedah umum, obgyn (SC, kuretase), minor. | M19: =IF(A19="","",SUMIF('14_Ruang'!$L:$L,A19,'14_Ruang'!$M:$M))
A20: PB16 | B20: 16 | C20: Kamar Bersalin (VK) | D20: Final Penunjang / Tindakan | G20: Persalinan & Kebidanan (VK) | H20: Tidak | I20: persalinan | K20: Persalinan normal dan tindakan kebidanan. | M20: =IF(A20="","",SUMIF('14_Ruang'!$L:$L,A20,'14_Ruang'!$M:$M))
A21: PB17 | B21: 17 | C21: Rehabilitasi Medik | D21: Final Penunjang / Tindakan | G21: Rehabilitasi Medik | H21: Tidak | I21: sesi | K21: Fisioterapi. | M21: =IF(A21="","",SUMIF('14_Ruang'!$L:$L,A21,'14_Ruang'!$M:$M))
A22: PB18 | B22: 18 | C22: Gigi | D22: Final Rawat Jalan | G22: Gigi (Dental) | H22: Tidak | I22: kunjungan | K22: Poli gigi umum. | M22: =IF(A22="","",SUMIF('14_Ruang'!$L:$L,A22,'14_Ruang'!$M:$M))
M23: =IF(A23="","",SUMIF('14_Ruang'!$L:$L,A23,'14_Ruang'!$M:$M))
M24: =IF(A24="","",SUMIF('14_Ruang'!$L:$L,A24,'14_Ruang'!$M:$M))
M25: =IF(A25="","",SUMIF('14_Ruang'!$L:$L,A25,'14_Ruang'!$M:$M))
M26: =IF(A26="","",SUMIF('14_Ruang'!$L:$L,A26,'14_Ruang'!$M:$M))
M27: =IF(A27="","",SUMIF('14_Ruang'!$L:$L,A27,'14_Ruang'!$M:$M))
M28: =IF(A28="","",SUMIF('14_Ruang'!$L:$L,A28,'14_Ruang'!$M:$M))
M29: =IF(A29="","",SUMIF('14_Ruang'!$L:$L,A29,'14_Ruang'!$M:$M))
M30: =IF(A30="","",SUMIF('14_Ruang'!$L:$L,A30,'14_Ruang'!$M:$M))
M31: =IF(A31="","",SUMIF('14_Ruang'!$L:$L,A31,'14_Ruang'!$M:$M))
M32: =IF(A32="","",SUMIF('14_Ruang'!$L:$L,A32,'14_Ruang'!$M:$M))
M33: =IF(A33="","",SUMIF('14_Ruang'!$L:$L,A33,'14_Ruang'!$M:$M))
M34: =IF(A34="","",SUMIF('14_Ruang'!$L:$L,A34,'14_Ruang'!$M:$M))
... M64: =IF(A64="","",SUMIF('14_Ruang'!$L:$L,A64,'14_Ruang'!$M:$M))

Sheet 09_Statistik_Alokasi
A1: 09 · Statistik Dasar Alokasi per Pusat Biaya
A2: Angka pembagi untuk step-down. Satu baris per pusat biaya (kode dari sheet 08). Kolom ISI: ketik angka; pada kolom bertanda "VOLUME" boleh mengetik kata VOLUME (= ambil dari volume kegiatan unit final), pada "Jumlah Hari rawat" boleh mengetik HARI RAWAT (= volume × LOS). Kolom abu-abu dihitung aplikasi.
A3: ISI | B3: OTOMATIS | C3: ISI | D3: OTOMATIS | E3: ISI | F3: OTOMATIS | G3: ISI | H3: ISI | I3: ISI | J3: ISI | K3: OTOMATIS | L3: OTOMATIS | M3: OTOMATIS | N3: ISI | O3: ISI | P3: ISI
A4: Kode PB | B4: Nama Pusat Biaya | C4: Jumlah pegawai | D4: Luas lantai | E4: Jumlah Kg cucian | F4: Pendapatan (Rp) | G4: Jumlah tindakan | H4: Jumlah pasien rawat inap | I4: Jumlah Hari rawat | J4: Jumlah Kunjungan Rawat Jalan | K4: Total Hari Rawat dan Kunjungan | L4: Direct cost | M4: Jumlah pasien yang ditangani | N4: Jumlah resep | O4: Jumlah pemeriksaan | P4: Jumlah kendaraan
A5: PB01 | B5: =IF(A5="","",IFERROR(INDEX('08_Pusat_Biaya'!$C$5:$C$64,MATCH(A5,'08_Pusat_Biaya'!$A$5:$A$64,0)),"⚠ kode tidak ditemukan")) | D5: =IF($A5="","",SUMIF('14_Ruang'!$L$5:$L$404,$A5,'14_Ruang'!$M$5:$M$404)) | F5: =IF($A5="","",IFERROR(IF(LEFT(INDEX('08_Pusat_Biaya'!$D$5:$D$64,MATCH($A5,'08_Pusat_Biaya'!$A$5:$A$64,0)),5)="Final",N(INDEX('08_Pusat_Biaya'!$J$5:$J$64,MATCH($A5,'08_Pusat_Biaya'!$A$5:$A$64,0))),0),0)) | K5: (dihitung aplikasi) | L5: (dihitung aplikasi) | M5: (dihitung aplikasi)
A6: PB02 | B6: =IF(A6="","",IFERROR(INDEX('08_Pusat_Biaya'!$C$5:$C$64,MATCH(A6,'08_Pusat_Biaya'!$A$5:$A$64,0)),"⚠ kode tidak ditemukan")) | D6: =IF($A6="","",SUMIF('14_Ruang'!$L$5:$L$404,$A6,'14_Ruang'!$M$5:$M$404)) | F6: =IF($A6="","",IFERROR(IF(LEFT(INDEX('08_Pusat_Biaya'!$D$5:$D$64,MATCH($A6,'08_Pusat_Biaya'!$A$5:$A$64,0)),5)="Final",N(INDEX('08_Pusat_Biaya'!$J$5:$J$64,MATCH($A6,'08_Pusat_Biaya'!$A$5:$A$64,0))),0),0)) | K6: (dihitung aplikasi) | L6: (dihitung aplikasi) | M6: (dihitung aplikasi)
A7: PB03 | B7: =IF(A7="","",IFERROR(INDEX('08_Pusat_Biaya'!$C$5:$C$64,MATCH(A7,'08_Pusat_Biaya'!$A$5:$A$64,0)),"⚠ kode tidak ditemukan")) | D7: =IF($A7="","",SUMIF('14_Ruang'!$L$5:$L$404,$A7,'14_Ruang'!$M$5:$M$404)) | F7: =IF($A7="","",IFERROR(IF(LEFT(INDEX('08_Pusat_Biaya'!$D$5:$D$64,MATCH($A7,'08_Pusat_Biaya'!$A$5:$A$64,0)),5)="Final",N(INDEX('08_Pusat_Biaya'!$J$5:$J$64,MATCH($A7,'08_Pusat_Biaya'!$A$5:$A$64,0))),0),0)) | K7: (dihitung aplikasi) | L7: (dihitung aplikasi) | M7: (dihitung aplikasi)
A8: PB04 | B8: =IF(A8="","",IFERROR(INDEX('08_Pusat_Biaya'!$C$5:$C$64,MATCH(A8,'08_Pusat_Biaya'!$A$5:$A$64,0)),"⚠ kode tidak ditemukan")) | D8: =IF($A8="","",SUMIF('14_Ruang'!$L$5:$L$404,$A8,'14_Ruang'!$M$5:$M$404)) | F8: =IF($A8="","",IFERROR(IF(LEFT(INDEX('08_Pusat_Biaya'!$D$5:$D$64,MATCH($A8,'08_Pusat_Biaya'!$A$5:$A$64,0)),5)="Final",N(INDEX('08_Pusat_Biaya'!$J$5:$J$64,MATCH($A8,'08_Pusat_Biaya'!$A$5:$A$64,0))),0),0)) | K8: (dihitung aplikasi) | L8: (dihitung aplikasi) | M8: (dihitung aplikasi)
A9: PB05 | B9: =IF(A9="","",IFERROR(INDEX('08_Pusat_Biaya'!$C$5:$C$64,MATCH(A9,'08_Pusat_Biaya'!$A$5:$A$64,0)),"⚠ kode tidak ditemukan")) | D9: =IF($A9="","",SUMIF('14_Ruang'!$L$5:$L$404,$A9,'14_Ruang'!$M$5:$M$404)) | F9: =IF($A9="","",IFERROR(IF(LEFT(INDEX('08_Pusat_Biaya'!$D$5:$D$64,MATCH($A9,'08_Pusat_Biaya'!$A$5:$A$64,0)),5)="Final",N(INDEX('08_Pusat_Biaya'!$J$5:$J$64,MATCH($A9,'08_Pusat_Biaya'!$A$5:$A$64,0))),0),0)) | K9: (dihitung aplikasi) | L9: (dihitung aplikasi) | M9: (dihitung aplikasi)
A10: PB06 | B10: =IF(A10="","",IFERROR(INDEX('08_Pusat_Biaya'!$C$5:$C$64,MATCH(A10,'08_Pusat_Biaya'!$A$5:$A$64,0)),"⚠ kode tidak ditemukan")) | D10: =IF($A10="","",SUMIF('14_Ruang'!$L$5:$L$404,$A10,'14_Ruang'!$M$5:$M$404)) | F10: =IF($A10="","",IFERROR(IF(LEFT(INDEX('08_Pusat_Biaya'!$D$5:$D$64,MATCH($A10,'08_Pusat_Biaya'!$A$5:$A$64,0)),5)="Final",N(INDEX('08_Pusat_Biaya'!$J$5:$J$64,MATCH($A10,'08_Pusat_Biaya'!$A$5:$A$64,0))),0),0)) | K10: (dihitung aplikasi) | L10: (dihitung aplikasi) | M10: (dihitung aplikasi)
A11: PB07 | B11: =IF(A11="","",IFERROR(INDEX('08_Pusat_Biaya'!$C$5:$C$64,MATCH(A11,'08_Pusat_Biaya'!$A$5:$A$64,0)),"⚠ kode tidak ditemukan")) | D11: =IF($A11="","",SUMIF('14_Ruang'!$L$5:$L$404,$A11,'14_Ruang'!$M$5:$M$404)) | F11: =IF($A11="","",IFERROR(IF(LEFT(INDEX('08_Pusat_Biaya'!$D$5:$D$64,MATCH($A11,'08_Pusat_Biaya'!$A$5:$A$64,0)),5)="Final",N(INDEX('08_Pusat_Biaya'!$J$5:$J$64,MATCH($A11,'08_Pusat_Biaya'!$A$5:$A$64,0))),0),0)) | K11: (dihitung aplikasi) | L11: (dihitung aplikasi) | M11: (dihitung aplikasi)
A12: PB08 | B12: =IF(A12="","",IFERROR(INDEX('08_Pusat_Biaya'!$C$5:$C$64,MATCH(A12,'08_Pusat_Biaya'!$A$5:$A$64,0)),"⚠ kode tidak ditemukan")) | D12: =IF($A12="","",SUMIF('14_Ruang'!$L$5:$L$404,$A12,'14_Ruang'!$M$5:$M$404)) | F12: =IF($A12="","",IFERROR(IF(LEFT(INDEX('08_Pusat_Biaya'!$D$5:$D$64,MATCH($A12,'08_Pusat_Biaya'!$A$5:$A$64,0)),5)="Final",N(INDEX('08_Pusat_Biaya'!$J$5:$J$64,MATCH($A12,'08_Pusat_Biaya'!$A$5:$A$64,0))),0),0)) | K12: (dihitung aplikasi) | L12: (dihitung aplikasi) | M12: (dihitung aplikasi)
A13: PB09 | B13: =IF(A13="","",IFERROR(INDEX('08_Pusat_Biaya'!$C$5:$C$64,MATCH(A13,'08_Pusat_Biaya'!$A$5:$A$64,0)),"⚠ kode tidak ditemukan")) | D13: =IF($A13="","",SUMIF('14_Ruang'!$L$5:$L$404,$A13,'14_Ruang'!$M$5:$M$404)) | F13: =IF($A13="","",IFERROR(IF(LEFT(INDEX('08_Pusat_Biaya'!$D$5:$D$64,MATCH($A13,'08_Pusat_Biaya'!$A$5:$A$64,0)),5)="Final",N(INDEX('08_Pusat_Biaya'!$J$5:$J$64,MATCH($A13,'08_Pusat_Biaya'!$A$5:$A$64,0))),0),0)) | K13: (dihitung aplikasi) | L13: (dihitung aplikasi) | M13: (dihitung aplikasi)
A14: PB10 | B14: =IF(A14="","",IFERROR(INDEX('08_Pusat_Biaya'!$C$5:$C$64,MATCH(A14,'08_Pusat_Biaya'!$A$5:$A$64,0)),"⚠ kode tidak ditemukan")) | D14: =IF($A14="","",SUMIF('14_Ruang'!$L$5:$L$404,$A14,'14_Ruang'!$M$5:$M$404)) | F14: =IF($A14="","",IFERROR(IF(LEFT(INDEX('08_Pusat_Biaya'!$D$5:$D$64,MATCH($A14,'08_Pusat_Biaya'!$A$5:$A$64,0)),5)="Final",N(INDEX('08_Pusat_Biaya'!$J$5:$J$64,MATCH($A14,'08_Pusat_Biaya'!$A$5:$A$64,0))),0),0)) | K14: (dihitung aplikasi) | L14: (dihitung aplikasi) | M14: (dihitung aplikasi)
A15: PB11 | B15: =IF(A15="","",IFERROR(INDEX('08_Pusat_Biaya'!$C$5:$C$64,MATCH(A15,'08_Pusat_Biaya'!$A$5:$A$64,0)),"⚠ kode tidak ditemukan")) | D15: =IF($A15="","",SUMIF('14_Ruang'!$L$5:$L$404,$A15,'14_Ruang'!$M$5:$M$404)) | F15: =IF($A15="","",IFERROR(IF(LEFT(INDEX('08_Pusat_Biaya'!$D$5:$D$64,MATCH($A15,'08_Pusat_Biaya'!$A$5:$A$64,0)),5)="Final",N(INDEX('08_Pusat_Biaya'!$J$5:$J$64,MATCH($A15,'08_Pusat_Biaya'!$A$5:$A$64,0))),0),0)) | K15: (dihitung aplikasi) | L15: (dihitung aplikasi) | M15: (dihitung aplikasi)
A16: PB12 | B16: =IF(A16="","",IFERROR(INDEX('08_Pusat_Biaya'!$C$5:$C$64,MATCH(A16,'08_Pusat_Biaya'!$A$5:$A$64,0)),"⚠ kode tidak ditemukan")) | D16: =IF($A16="","",SUMIF('14_Ruang'!$L$5:$L$404,$A16,'14_Ruang'!$M$5:$M$404)) | F16: =IF($A16="","",IFERROR(IF(LEFT(INDEX('08_Pusat_Biaya'!$D$5:$D$64,MATCH($A16,'08_Pusat_Biaya'!$A$5:$A$64,0)),5)="Final",N(INDEX('08_Pusat_Biaya'!$J$5:$J$64,MATCH($A16,'08_Pusat_Biaya'!$A$5:$A$64,0))),0),0)) | K16: (dihitung aplikasi) | L16: (dihitung aplikasi) | M16: (dihitung aplikasi)
... A22: PB18 | B22: =IF(A22="","",IFERROR(INDEX('08_Pusat_Biaya'!$C$5:$C$64,MATCH(A22,'08_Pusat_Biaya'!$A$5:$A$64,0)),"⚠ kode tidak ditemukan")) | D22: =IF($A22="","",SUMIF('14_Ruang'!$L$5:$L$404,$A22,'14_Ruang'!$M$5:$M$404)) | F22: =IF($A22="","",IFERROR(IF(LEFT(INDEX('08_Pusat_Biaya'!$D$5:$D$64,MATCH($A22,'08_Pusat_Biaya'!$A$5:$A$64,0)),5)="Final",N(INDEX('08_Pusat_Biaya'!$J$5:$J$64,MATCH($A22,'08_Pusat_Biaya'!$A$5:$A$64,0))),0),0)) | K22: (dihitung aplikasi) | L22: (dihitung aplikasi) | M22: (dihitung aplikasi)
B23: =IF(A23="","",IFERROR(INDEX('08_Pusat_Biaya'!$C$5:$C$64,MATCH(A23,'08_Pusat_Biaya'!$A$5:$A$64,0)),"⚠ kode tidak ditemukan")) | D23: =IF($A23="","",SUMIF('14_Ruang'!$L$5:$L$404,$A23,'14_Ruang'!$M$5:$M$404)) | F23: =IF($A23="","",IFERROR(IF(LEFT(INDEX('08_Pusat_Biaya'!$D$5:$D$64,MATCH($A23,'08_Pusat_Biaya'!$A$5:$A$64,0)),5)="Final",N(INDEX('08_Pusat_Biaya'!$J$5:$J$64,MATCH($A23,'08_Pusat_Biaya'!$A$5:$A$64,0))),0),0)) | K23: (dihitung aplikasi) | L23: (dihitung aplikasi) | M23: (dihitung aplikasi)
B24: =IF(A24="","",IFERROR(INDEX('08_Pusat_Biaya'!$C$5:$C$64,MATCH(A24,'08_Pusat_Biaya'!$A$5:$A$64,0)),"⚠ kode tidak ditemukan")) | D24: =IF($A24="","",SUMIF('14_Ruang'!$L$5:$L$404,$A24,'14_Ruang'!$M$5:$M$404)) | F24: =IF($A24="","",IFERROR(IF(LEFT(INDEX('08_Pusat_Biaya'!$D$5:$D$64,MATCH($A24,'08_Pusat_Biaya'!$A$5:$A$64,0)),5)="Final",N(INDEX('08_Pusat_Biaya'!$J$5:$J$64,MATCH($A24,'08_Pusat_Biaya'!$A$5:$A$64,0))),0),0)) | K24: (dihitung aplikasi) | L24: (dihitung aplikasi) | M24: (dihitung aplikasi)
B25: =IF(A25="","",IFERROR(INDEX('08_Pusat_Biaya'!$C$5:$C$64,MATCH(A25,'08_Pusat_Biaya'!$A$5:$A$64,0)),"⚠ kode tidak ditemukan")) | D25: =IF($A25="","",SUMIF('14_Ruang'!$L$5:$L$404,$A25,'14_Ruang'!$M$5:$M$404)) | F25: =IF($A25="","",IFERROR(IF(LEFT(INDEX('08_Pusat_Biaya'!$D$5:$D$64,MATCH($A25,'08_Pusat_Biaya'!$A$5:$A$64,0)),5)="Final",N(INDEX('08_Pusat_Biaya'!$J$5:$J$64,MATCH($A25,'08_Pusat_Biaya'!$A$5:$A$64,0))),0),0)) | K25: (dihitung aplikasi) | L25: (dihitung aplikasi) | M25: (dihitung aplikasi)
B26: =IF(A26="","",IFERROR(INDEX('08_Pusat_Biaya'!$C$5:$C$64,MATCH(A26,'08_Pusat_Biaya'!$A$5:$A$64,0)),"⚠ kode tidak ditemukan")) | D26: =IF($A26="","",SUMIF('14_Ruang'!$L$5:$L$404,$A26,'14_Ruang'!$M$5:$M$404)) | F26: =IF($A26="","",IFERROR(IF(LEFT(INDEX('08_Pusat_Biaya'!$D$5:$D$64,MATCH($A26,'08_Pusat_Biaya'!$A$5:$A$64,0)),5)="Final",N(INDEX('08_Pusat_Biaya'!$J$5:$J$64,MATCH($A26,'08_Pusat_Biaya'!$A$5:$A$64,0))),0),0)) | K26: (dihitung aplikasi) | L26: (dihitung aplikasi) | M26: (dihitung aplikasi)
B27: =IF(A27="","",IFERROR(INDEX('08_Pusat_Biaya'!$C$5:$C$64,MATCH(A27,'08_Pusat_Biaya'!$A$5:$A$64,0)),"⚠ kode tidak ditemukan")) | D27: =IF($A27="","",SUMIF('14_Ruang'!$L$5:$L$404,$A27,'14_Ruang'!$M$5:$M$404)) | F27: =IF($A27="","",IFERROR(IF(LEFT(INDEX('08_Pusat_Biaya'!$D$5:$D$64,MATCH($A27,'08_Pusat_Biaya'!$A$5:$A$64,0)),5)="Final",N(INDEX('08_Pusat_Biaya'!$J$5:$J$64,MATCH($A27,'08_Pusat_Biaya'!$A$5:$A$64,0))),0),0)) | K27: (dihitung aplikasi) | L27: (dihitung aplikasi) | M27: (dihitung aplikasi)
B28: =IF(A28="","",IFERROR(INDEX('08_Pusat_Biaya'!$C$5:$C$64,MATCH(A28,'08_Pusat_Biaya'!$A$5:$A$64,0)),"⚠ kode tidak ditemukan")) | D28: =IF($A28="","",SUMIF('14_Ruang'!$L$5:$L$404,$A28,'14_Ruang'!$M$5:$M$404)) | F28: =IF($A28="","",IFERROR(IF(LEFT(INDEX('08_Pusat_Biaya'!$D$5:$D$64,MATCH($A28,'08_Pusat_Biaya'!$A$5:$A$64,0)),5)="Final",N(INDEX('08_Pusat_Biaya'!$J$5:$J$64,MATCH($A28,'08_Pusat_Biaya'!$A$5:$A$64,0))),0),0)) | K28: (dihitung aplikasi) | L28: (dihitung aplikasi) | M28: (dihitung aplikasi)
B29: =IF(A29="","",IFERROR(INDEX('08_Pusat_Biaya'!$C$5:$C$64,MATCH(A29,'08_Pusat_Biaya'!$A$5:$A$64,0)),"⚠ kode tidak ditemukan")) | D29: =IF($A29="","",SUMIF('14_Ruang'!$L$5:$L$404,$A29,'14_Ruang'!$M$5:$M$404)) | F29: =IF($A29="","",IFERROR(IF(LEFT(INDEX('08_Pusat_Biaya'!$D$5:$D$64,MATCH($A29,'08_Pusat_Biaya'!$A$5:$A$64,0)),5)="Final",N(INDEX('08_Pusat_Biaya'!$J$5:$J$64,MATCH($A29,'08_Pusat_Biaya'!$A$5:$A$64,0))),0),0)) | K29: (dihitung aplikasi) | L29: (dihitung aplikasi) | M29: (dihitung aplikasi)
B30: =IF(A30="","",IFERROR(INDEX('08_Pusat_Biaya'!$C$5:$C$64,MATCH(A30,'08_Pusat_Biaya'!$A$5:$A$64,0)),"⚠ kode tidak ditemukan")) | D30: =IF($A30="","",SUMIF('14_Ruang'!$L$5:$L$404,$A30,'14_Ruang'!$M$5:$M$404)) | F30: =IF($A30="","",IFERROR(IF(LEFT(INDEX('08_Pusat_Biaya'!$D$5:$D$64,MATCH($A30,'08_Pusat_Biaya'!$A$5:$A$64,0)),5)="Final",N(INDEX('08_Pusat_Biaya'!$J$5:$J$64,MATCH($A30,'08_Pusat_Biaya'!$A$5:$A$64,0))),0),0)) | K30: (dihitung aplikasi) | L30: (dihitung aplikasi) | M30: (dihitung aplikasi)
B31: =IF(A31="","",IFERROR(INDEX('08_Pusat_Biaya'!$C$5:$C$64,MATCH(A31,'08_Pusat_Biaya'!$A$5:$A$64,0)),"⚠ kode tidak ditemukan")) | D31: =IF($A31="","",SUMIF('14_Ruang'!$L$5:$L$404,$A31,'14_Ruang'!$M$5:$M$404)) | F31: =IF($A31="","",IFERROR(IF(LEFT(INDEX('08_Pusat_Biaya'!$D$5:$D$64,MATCH($A31,'08_Pusat_Biaya'!$A$5:$A$64,0)),5)="Final",N(INDEX('08_Pusat_Biaya'!$J$5:$J$64,MATCH($A31,'08_Pusat_Biaya'!$A$5:$A$64,0))),0),0)) | K31: (dihitung aplikasi) | L31: (dihitung aplikasi) | M31: (dihitung aplikasi)
B32: =IF(A32="","",IFERROR(INDEX('08_Pusat_Biaya'!$C$5:$C$64,MATCH(A32,'08_Pusat_Biaya'!$A$5:$A$64,0)),"⚠ kode tidak ditemukan")) | D32: =IF($A32="","",SUMIF('14_Ruang'!$L$5:$L$404,$A32,'14_Ruang'!$M$5:$M$404)) | F32: =IF($A32="","",IFERROR(IF(LEFT(INDEX('08_Pusat_Biaya'!$D$5:$D$64,MATCH($A32,'08_Pusat_Biaya'!$A$5:$A$64,0)),5)="Final",N(INDEX('08_Pusat_Biaya'!$J$5:$J$64,MATCH($A32,'08_Pusat_Biaya'!$A$5:$A$64,0))),0),0)) | K32: (dihitung aplikasi) | L32: (dihitung aplikasi) | M32: (dihitung aplikasi)
B33: =IF(A33="","",IFERROR(INDEX('08_Pusat_Biaya'!$C$5:$C$64,MATCH(A33,'08_Pusat_Biaya'!$A$5:$A$64,0)),"⚠ kode tidak ditemukan")) | D33: =IF($A33="","",SUMIF('14_Ruang'!$L$5:$L$404,$A33,'14_Ruang'!$M$5:$M$404)) | F33: =IF($A33="","",IFERROR(IF(LEFT(INDEX('08_Pusat_Biaya'!$D$5:$D$64,MATCH($A33,'08_Pusat_Biaya'!$A$5:$A$64,0)),5)="Final",N(INDEX('08_Pusat_Biaya'!$J$5:$J$64,MATCH($A33,'08_Pusat_Biaya'!$A$5:$A$64,0))),0),0)) | K33: (dihitung aplikasi) | L33: (dihitung aplikasi) | M33: (dihitung aplikasi)
B34: =IF(A34="","",IFERROR(INDEX('08_Pusat_Biaya'!$C$5:$C$64,MATCH(A34,'08_Pusat_Biaya'!$A$5:$A$64,0)),"⚠ kode tidak ditemukan")) | D34: =IF($A34="","",SUMIF('14_Ruang'!$L$5:$L$404,$A34,'14_Ruang'!$M$5:$M$404)) | F34: =IF($A34="","",IFERROR(IF(LEFT(INDEX('08_Pusat_Biaya'!$D$5:$D$64,MATCH($A34,'08_Pusat_Biaya'!$A$5:$A$64,0)),5)="Final",N(INDEX('08_Pusat_Biaya'!$J$5:$J$64,MATCH($A34,'08_Pusat_Biaya'!$A$5:$A$64,0))),0),0)) | K34: (dihitung aplikasi) | L34: (dihitung aplikasi) | M34: (dihitung aplikasi)
... B64: =IF(A64="","",IFERROR(INDEX('08_Pusat_Biaya'!$C$5:$C$64,MATCH(A64,'08_Pusat_Biaya'!$A$5:$A$64,0)),"⚠ kode tidak ditemukan")) | D64: =IF($A64="","",SUMIF('14_Ruang'!$L$5:$L$404,$A64,'14_Ruang'!$M$5:$M$404)) | F64: =IF($A64="","",IFERROR(IF(LEFT(INDEX('08_Pusat_Biaya'!$D$5:$D$64,MATCH($A64,'08_Pusat_Biaya'!$A$5:$A$64,0)),5)="Final",N(INDEX('08_Pusat_Biaya'!$J$5:$J$64,MATCH($A64,'08_Pusat_Biaya'!$A$5:$A$64,0))),0),0)) | K64: (dihitung aplikasi) | L64: (dihitung aplikasi) | M64: (dihitung aplikasi)

Sheet 10_Biaya_Tdk_Langsung
A1: 10 · Biaya Tidak Langsung RS (pool overhead)
A2: Isi biaya setahun tiap uraian (kolom kuning). Uraian & kategori sudah terisi standar – sesuaikan/tambah baris bila perlu. Kode pusat biaya diatur pendamping.
A3: PERIKSA / SESUAIKAN | B3: PERIKSA / SESUAIKAN | C3: WAJIB DIISI | D3: DIATUR PENDAMPING | E3: PERIKSA / SESUAIKAN | F3: OPSIONAL | G3: OTOMATIS
A4: Kode | B4: Uraian Biaya Tidak Langsung | C4: Biaya 1 Tahun (Rp) | D4: Kode PB Penanggung | E4: Kategori | F4: Sumber Data | G4: Nama Pusat Biaya
A5: OH01 | B5: Gaji & tunjangan direksi dan manajer (4 orang) | D5: PB01 | E5: Manajemen | F5: Simulasi: daftar gaji (13 bulan + BPJS pemberi kerja 6%) | G5: =IF(D5="","",IFERROR(INDEX('08_Pusat_Biaya'!$C:$C,MATCH(D5,'08_Pusat_Biaya'!$A:$A,0)),"⚠ kode tidak ditemukan"))
A6: OH02 | B6: Gaji & tunjangan staf administrasi (10 orang: keuangan, SDM, IT, mutu, humas, sekretariat) | D6: PB01 | E6: Administrasi | F6: Simulasi: daftar gaji staf administrasi | G6: =IF(D6="","",IFERROR(INDEX('08_Pusat_Biaya'!$C:$C,MATCH(D6,'08_Pusat_Biaya'!$A:$A,0)),"⚠ kode tidak ditemukan"))
A7: OH03 | B7: ATK, cetakan dan perlengkapan kantor | D7: PB01 | E7: Administrasi | F7: Simulasi: ±Rp 1,9 jt/pegawai/tahun + formulir cetak | G7: =IF(D7="","",IFERROR(INDEX('08_Pusat_Biaya'!$C:$C,MATCH(D7,'08_Pusat_Biaya'!$A:$A,0)),"⚠ kode tidak ditemukan"))
A8: OH04 | B8: Sistem informasi (SIMRS), lisensi dan jaringan internet | D8: PB01 | E8: Administrasi | F8: Simulasi: lisensi SIMRS + internet + pemeliharaan | G8: =IF(D8="","",IFERROR(INDEX('08_Pusat_Biaya'!$C:$C,MATCH(D8,'08_Pusat_Biaya'!$A:$A,0)),"⚠ kode tidak ditemukan"))
A9: OH05 | B9: Pemasaran, humas dan pengembangan SDM (diklat) | D9: PB01 | E9: Manajemen | F9: Simulasi: anggaran tahunan | G9: =IF(D9="","",IFERROR(INDEX('08_Pusat_Biaya'!$C:$C,MATCH(D9,'08_Pusat_Biaya'!$A:$A,0)),"⚠ kode tidak ditemukan"))
A10: OH06 | B10: Asuransi aset, perizinan & akreditasi | D10: PB01 | E10: Administrasi | F10: Simulasi: premi asuransi + biaya survei akreditasi | G10: =IF(D10="","",IFERROR(INDEX('08_Pusat_Biaya'!$C:$C,MATCH(D10,'08_Pusat_Biaya'!$A:$A,0)),"⚠ kode tidak ditemukan"))
A11: OH07 | B11: Honor komite, konsultan hukum, audit & pajak | D11: PB01 | E11: Manajemen | F11: Simulasi: kontrak jasa profesional | G11: =IF(D11="","",IFERROR(INDEX('08_Pusat_Biaya'!$C:$C,MATCH(D11,'08_Pusat_Biaya'!$A:$A,0)),"⚠ kode tidak ditemukan"))
A12: OH08 | B12: PBB, retribusi & pajak daerah | D12: PB01 | E12: Administrasi | F12: Simulasi: ±Rp 23 ribu/m² lantai | G12: =IF(D12="","",IFERROR(INDEX('08_Pusat_Biaya'!$C:$C,MATCH(D12,'08_Pusat_Biaya'!$A:$A,0)),"⚠ kode tidak ditemukan"))
A13: OH09 | B13: Gaji petugas kebersihan, keamanan, sopir & gudang (17 orang) | D13: PB02 | E13: Fasilitas | F13: Simulasi: daftar gaji; UMK Jateng 2026 ±Rp 2,3–3,7 jt | G13: =IF(D13="","",IFERROR(INDEX('08_Pusat_Biaya'!$C:$C,MATCH(D13,'08_Pusat_Biaya'!$A:$A,0)),"⚠ kode tidak ditemukan"))
A14: OH10 | B14: Bahan kebersihan, seragam satpam & perlengkapan keamanan | D14: PB02 | E14: Fasilitas | F14: Simulasi: ±Rp 3,1 jt/TT/tahun | G14: =IF(D14="","",IFERROR(INDEX('08_Pusat_Biaya'!$C:$C,MATCH(D14,'08_Pusat_Biaya'!$A:$A,0)),"⚠ kode tidak ditemukan"))
A15: OH11 | B15: Air PDAM, telepon dan utilitas lain (di luar listrik) | D15: PB02 | E15: Utilitas | F15: Simulasi: ±600 liter/TT/hari × tarif PDAM | G15: =IF(D15="","",IFERROR(INDEX('08_Pusat_Biaya'!$C:$C,MATCH(D15,'08_Pusat_Biaya'!$A:$A,0)),"⚠ kode tidak ditemukan"))
A16: OH12 | B16: Pengelolaan limbah medis B3 (pihak ketiga) dan limbah cair | D16: PB02 | E16: Penunjang Umum | F16: Simulasi: kontrak pihak ketiga | G16: =IF(D16="","",IFERROR(INDEX('08_Pusat_Biaya'!$C:$C,MATCH(D16,'08_Pusat_Biaya'!$A:$A,0)),"⚠ kode tidak ditemukan"))
... A25: OH21 | B25: Gaji petugas CSSD (3 orang) | D25: PB09 | E25: Penunjang Umum | F25: Simulasi: daftar gaji | G25: =IF(D25="","",IFERROR(INDEX('08_Pusat_Biaya'!$C:$C,MATCH(D25,'08_Pusat_Biaya'!$A:$A,0)),"⚠ kode tidak ditemukan"))
G26: =IF(D26="","",IFERROR(INDEX('08_Pusat_Biaya'!$C:$C,MATCH(D26,'08_Pusat_Biaya'!$A:$A,0)),"⚠ kode tidak ditemukan"))
G27: =IF(D27="","",IFERROR(INDEX('08_Pusat_Biaya'!$C:$C,MATCH(D27,'08_Pusat_Biaya'!$A:$A,0)),"⚠ kode tidak ditemukan"))
G28: =IF(D28="","",IFERROR(INDEX('08_Pusat_Biaya'!$C:$C,MATCH(D28,'08_Pusat_Biaya'!$A:$A,0)),"⚠ kode tidak ditemukan"))
G29: =IF(D29="","",IFERROR(INDEX('08_Pusat_Biaya'!$C:$C,MATCH(D29,'08_Pusat_Biaya'!$A:$A,0)),"⚠ kode tidak ditemukan"))
G30: =IF(D30="","",IFERROR(INDEX('08_Pusat_Biaya'!$C:$C,MATCH(D30,'08_Pusat_Biaya'!$A:$A,0)),"⚠ kode tidak ditemukan"))
G31: =IF(D31="","",IFERROR(INDEX('08_Pusat_Biaya'!$C:$C,MATCH(D31,'08_Pusat_Biaya'!$A:$A,0)),"⚠ kode tidak ditemukan"))
G32: =IF(D32="","",IFERROR(INDEX('08_Pusat_Biaya'!$C:$C,MATCH(D32,'08_Pusat_Biaya'!$A:$A,0)),"⚠ kode tidak ditemukan"))
G33: =IF(D33="","",IFERROR(INDEX('08_Pusat_Biaya'!$C:$C,MATCH(D33,'08_Pusat_Biaya'!$A:$A,0)),"⚠ kode tidak ditemukan"))
G34: =IF(D34="","",IFERROR(INDEX('08_Pusat_Biaya'!$C:$C,MATCH(D34,'08_Pusat_Biaya'!$A:$A,0)),"⚠ kode tidak ditemukan"))
G35: =IF(D35="","",IFERROR(INDEX('08_Pusat_Biaya'!$C:$C,MATCH(D35,'08_Pusat_Biaya'!$A:$A,0)),"⚠ kode tidak ditemukan"))
G36: =IF(D36="","",IFERROR(INDEX('08_Pusat_Biaya'!$C:$C,MATCH(D36,'08_Pusat_Biaya'!$A:$A,0)),"⚠ kode tidak ditemukan"))
G37: =IF(D37="","",IFERROR(INDEX('08_Pusat_Biaya'!$C:$C,MATCH(D37,'08_Pusat_Biaya'!$A:$A,0)),"⚠ kode tidak ditemukan"))
... G84: =IF(D84="","",IFERROR(INDEX('08_Pusat_Biaya'!$C:$C,MATCH(D84,'08_Pusat_Biaya'!$A:$A,0)),"⚠ kode tidak ditemukan"))

Sheet 12_Kelompok_Tindakan
A1: 12 · Kelompok Tindakan → Unit Final
A2: Memetakan tiap kelompok tindakan ke pusat biaya Final. Pembagi kosong = memakai LOS (untuk rawat inap per hari); isi 0 bila overhead tidak dibebankan; isi 1 untuk rawat jalan.
A3: PERIKSA / SESUAIKAN | B3: DIATUR PENDAMPING | C3: DIATUR PENDAMPING | D3: OPSIONAL | E3: OTOMATIS
A4: Kelompok Tindakan | B4: Kode PB Final | C4: Pembagi | D4: Keterangan | E4: Nama Unit Final
A5: Konsultasi Rawat Jalan | B5: PB10 | C5: 1 | D5: Satu baris = satu kunjungan poliklinik. Volume kelompok ini = jumlah kunjungan rawat jalan (jangan dobel: tindakan tambahan ada di kelompok lain). | E5: =IF(B5="","",IFERROR(INDEX('08_Pusat_Biaya'!$C:$C,MATCH(B5,'08_Pusat_Biaya'!$A:$A,0)),"⚠ kode tidak ditemukan"))
A6: Tindakan Poliklinik | B6: PB10 | C6: 1 | D6: Tindakan tambahan di poli (EKG, nebulisasi, jahit, IUD, dll). TIDAK dihitung sebagai kunjungan. | E6: =IF(B6="","",IFERROR(INDEX('08_Pusat_Biaya'!$C:$C,MATCH(B6,'08_Pusat_Biaya'!$A:$A,0)),"⚠ kode tidak ditemukan"))
A7: Gigi (Dental) | B7: PB18 | C7: 1 | D7: Paket kunjungan gigi: tiap baris adalah satu jenis kunjungan, saling meniadakan. | E7: =IF(B7="","",IFERROR(INDEX('08_Pusat_Biaya'!$C:$C,MATCH(B7,'08_Pusat_Biaya'!$A:$A,0)),"⚠ kode tidak ditemukan"))
A8: IGD | B8: PB12 | C8: 1 | D8: Paket kunjungan IGD menurut tingkat kegawatan: saling meniadakan, jumlah = kunjungan IGD. | E8: =IF(B8="","",IFERROR(INDEX('08_Pusat_Biaya'!$C:$C,MATCH(B8,'08_Pusat_Biaya'!$A:$A,0)),"⚠ kode tidak ditemukan"))
A9: Patologi Klinik | B9: PB13 | C9: 1 | D9: Satu baris = satu jenis pemeriksaan laboratorium. | E9: =IF(B9="","",IFERROR(INDEX('08_Pusat_Biaya'!$C:$C,MATCH(B9,'08_Pusat_Biaya'!$A:$A,0)),"⚠ kode tidak ditemukan"))
A10: Radiologi | B10: PB14 | C10: 1 | D10: Satu baris = satu jenis pemeriksaan radiologi/USG. | E10: =IF(B10="","",IFERROR(INDEX('08_Pusat_Biaya'!$C:$C,MATCH(B10,'08_Pusat_Biaya'!$A:$A,0)),"⚠ kode tidak ditemukan"))
A11: Kamar Bedah | B11: PB15 | C11: 1 | D11: Satu baris = satu jenis operasi. Volume = jumlah operasi. | E11: =IF(B11="","",IFERROR(INDEX('08_Pusat_Biaya'!$C:$C,MATCH(B11,'08_Pusat_Biaya'!$A:$A,0)),"⚠ kode tidak ditemukan"))
A12: Persalinan & Kebidanan (VK) | B12: PB16 | C12: 1 | D12: Paket persalinan di VK: saling meniadakan. Operasi caesar dihitung di Kamar Bedah. | E12: =IF(B12="","",IFERROR(INDEX('08_Pusat_Biaya'!$C:$C,MATCH(B12,'08_Pusat_Biaya'!$A:$A,0)),"⚠ kode tidak ditemukan"))
A13: Rehabilitasi Medik | B13: PB17 | C13: 1 | D13: Per sesi terapi. | E13: =IF(B13="","",IFERROR(INDEX('08_Pusat_Biaya'!$C:$C,MATCH(B13,'08_Pusat_Biaya'!$A:$A,0)),"⚠ kode tidak ditemukan"))
A14: Rawat Inap – Kamar Perawatan | B14: PB11 | D14: Per HARI RAWAT menurut kelas. Pembagi dikosongkan = memakai LOS (aplikasi mengubah episode menjadi hari rawat). | E14: =IF(B14="","",IFERROR(INDEX('08_Pusat_Biaya'!$C:$C,MATCH(B14,'08_Pusat_Biaya'!$A:$A,0)),"⚠ kode tidak ditemukan"))
A15: Visite Dokter Rawat Inap | B15: PB11 | C15: 0 | D15: Visite dokter spesialis. Pembagi 0: overhead rawat inap sudah dibebankan pada tarif kamar per hari. | E15: =IF(B15="","",IFERROR(INDEX('08_Pusat_Biaya'!$C:$C,MATCH(B15,'08_Pusat_Biaya'!$A:$A,0)),"⚠ kode tidak ditemukan"))
A16: Tindakan Keperawatan Rawat Inap | B16: PB11 | C16: 0 | D16: Admisi, transfusi, pemeriksaan bayi baru lahir, dan tindakan lain di bangsal. Pembagi 0 sama seperti visite. | E16: =IF(B16="","",IFERROR(INDEX('08_Pusat_Biaya'!$C:$C,MATCH(B16,'08_Pusat_Biaya'!$A:$A,0)),"⚠ kode tidak ditemukan"))
E17: =IF(B17="","",IFERROR(INDEX('08_Pusat_Biaya'!$C:$C,MATCH(B17,'08_Pusat_Biaya'!$A:$A,0)),"⚠ kode tidak ditemukan"))
E18: =IF(B18="","",IFERROR(INDEX('08_Pusat_Biaya'!$C:$C,MATCH(B18,'08_Pusat_Biaya'!$A:$A,0)),"⚠ kode tidak ditemukan"))
E19: =IF(B19="","",IFERROR(INDEX('08_Pusat_Biaya'!$C:$C,MATCH(B19,'08_Pusat_Biaya'!$A:$A,0)),"⚠ kode tidak ditemukan"))
E20: =IF(B20="","",IFERROR(INDEX('08_Pusat_Biaya'!$C:$C,MATCH(B20,'08_Pusat_Biaya'!$A:$A,0)),"⚠ kode tidak ditemukan"))
E21: =IF(B21="","",IFERROR(INDEX('08_Pusat_Biaya'!$C:$C,MATCH(B21,'08_Pusat_Biaya'!$A:$A,0)),"⚠ kode tidak ditemukan"))
E22: =IF(B22="","",IFERROR(INDEX('08_Pusat_Biaya'!$C:$C,MATCH(B22,'08_Pusat_Biaya'!$A:$A,0)),"⚠ kode tidak ditemukan"))
E23: =IF(B23="","",IFERROR(INDEX('08_Pusat_Biaya'!$C:$C,MATCH(B23,'08_Pusat_Biaya'!$A:$A,0)),"⚠ kode tidak ditemukan"))
E24: =IF(B24="","",IFERROR(INDEX('08_Pusat_Biaya'!$C:$C,MATCH(B24,'08_Pusat_Biaya'!$A:$A,0)),"⚠ kode tidak ditemukan"))
E25: =IF(B25="","",IFERROR(INDEX('08_Pusat_Biaya'!$C:$C,MATCH(B25,'08_Pusat_Biaya'!$A:$A,0)),"⚠ kode tidak ditemukan"))
E26: =IF(B26="","",IFERROR(INDEX('08_Pusat_Biaya'!$C:$C,MATCH(B26,'08_Pusat_Biaya'!$A:$A,0)),"⚠ kode tidak ditemukan"))
E27: =IF(B27="","",IFERROR(INDEX('08_Pusat_Biaya'!$C:$C,MATCH(B27,'08_Pusat_Biaya'!$A:$A,0)),"⚠ kode tidak ditemukan"))
E28: =IF(B28="","",IFERROR(INDEX('08_Pusat_Biaya'!$C:$C,MATCH(B28,'08_Pusat_Biaya'!$A:$A,0)),"⚠ kode tidak ditemukan"))
... E84: =IF(B84="","",IFERROR(INDEX('08_Pusat_Biaya'!$C:$C,MATCH(B84,'08_Pusat_Biaya'!$A:$A,0)),"⚠ kode tidak ditemukan"))

Sheet 13_Profesi_SDM
A1: 13 · Profesi / SDM & penghasilan
A2: Satu baris per profesi/jabatan: penghasilan setahun per orang, jam kerja, menit hilang, dan jumlah orang. Kolom kuning wajib diisi.
A3: WAJIB DIISI | B3: WAJIB DIISI | C3: WAJIB DIISI | D3: WAJIB DIISI | E3: WAJIB DIISI | F3: WAJIB DIISI | G3: OPSIONAL | H3: OPSIONAL
A4: Kode Profesi | B4: Profesi / Jabatan | C4: Penghasilan 1 Tahun (Rp) | D4: Jam Kerja / Hari | E4: Menit Hilang / Hari | F4: Jumlah SDM | G4: Unit Pengguna Utama | H4: Keterangan

Sheet 14_Ruang
A1: 14 · Ruangan / Sarana (inventaris luas & pola layanan)
A2: Satu baris per ruangan: luas, jumlah, satuan, pola layanan, dan kapasitas simultan. Kolom kuning wajib diisi; kolom abu-abu terisi otomatis.
A3: WAJIB DIISI | B3: WAJIB DIISI | C3: WAJIB DIISI | D3: WAJIB DIISI | E3: WAJIB DIISI | F3: WAJIB DIISI | G3: WAJIB DIISI | H3: WAJIB DIISI | I3: OPSIONAL | J3: OTOMATIS | K3: OTOMATIS | L3: OTOMATIS | M3: OTOMATIS
A4: Kode Ruang | B4: Nama Ruangan | C4: Kode Unit | D4: Luas per Unit (m²) | E4: Jumlah Unit | F4: Satuan | G4: Pola Layanan | H4: Kapasitas Simultan | I4: Keterangan | J4: Nama Unit | K4: Jenis Unit | L4: Kode Pusat Biaya | M4: Total Luas (m²)
J5: =IF(C5="","",IFERROR(INDEX('07_Unit'!$B:$B,MATCH(C5,'07_Unit'!$A:$A,0)),"⚠ kode tidak ditemukan")) | K5: =IF(C5="","",IFERROR(INDEX('07_Unit'!$C:$C,MATCH(C5,'07_Unit'!$A:$A,0)),"⚠ kode tidak ditemukan")) | L5: =IF(C5="","",IFERROR(INDEX('07_Unit'!$D:$D,MATCH(C5,'07_Unit'!$A:$A,0)),"⚠ kode tidak ditemukan")) | M5: =IF(OR(D5="",E5=""),0,D5*E5)
J6: =IF(C6="","",IFERROR(INDEX('07_Unit'!$B:$B,MATCH(C6,'07_Unit'!$A:$A,0)),"⚠ kode tidak ditemukan")) | K6: =IF(C6="","",IFERROR(INDEX('07_Unit'!$C:$C,MATCH(C6,'07_Unit'!$A:$A,0)),"⚠ kode tidak ditemukan")) | L6: =IF(C6="","",IFERROR(INDEX('07_Unit'!$D:$D,MATCH(C6,'07_Unit'!$A:$A,0)),"⚠ kode tidak ditemukan")) | M6: =IF(OR(D6="",E6=""),0,D6*E6)
J7: =IF(C7="","",IFERROR(INDEX('07_Unit'!$B:$B,MATCH(C7,'07_Unit'!$A:$A,0)),"⚠ kode tidak ditemukan")) | K7: =IF(C7="","",IFERROR(INDEX('07_Unit'!$C:$C,MATCH(C7,'07_Unit'!$A:$A,0)),"⚠ kode tidak ditemukan")) | L7: =IF(C7="","",IFERROR(INDEX('07_Unit'!$D:$D,MATCH(C7,'07_Unit'!$A:$A,0)),"⚠ kode tidak ditemukan")) | M7: =IF(OR(D7="",E7=""),0,D7*E7)
J8: =IF(C8="","",IFERROR(INDEX('07_Unit'!$B:$B,MATCH(C8,'07_Unit'!$A:$A,0)),"⚠ kode tidak ditemukan")) | K8: =IF(C8="","",IFERROR(INDEX('07_Unit'!$C:$C,MATCH(C8,'07_Unit'!$A:$A,0)),"⚠ kode tidak ditemukan")) | L8: =IF(C8="","",IFERROR(INDEX('07_Unit'!$D:$D,MATCH(C8,'07_Unit'!$A:$A,0)),"⚠ kode tidak ditemukan")) | M8: =IF(OR(D8="",E8=""),0,D8*E8)
J9: =IF(C9="","",IFERROR(INDEX('07_Unit'!$B:$B,MATCH(C9,'07_Unit'!$A:$A,0)),"⚠ kode tidak ditemukan")) | K9: =IF(C9="","",IFERROR(INDEX('07_Unit'!$C:$C,MATCH(C9,'07_Unit'!$A:$A,0)),"⚠ kode tidak ditemukan")) | L9: =IF(C9="","",IFERROR(INDEX('07_Unit'!$D:$D,MATCH(C9,'07_Unit'!$A:$A,0)),"⚠ kode tidak ditemukan")) | M9: =IF(OR(D9="",E9=""),0,D9*E9)
J10: =IF(C10="","",IFERROR(INDEX('07_Unit'!$B:$B,MATCH(C10,'07_Unit'!$A:$A,0)),"⚠ kode tidak ditemukan")) | K10: =IF(C10="","",IFERROR(INDEX('07_Unit'!$C:$C,MATCH(C10,'07_Unit'!$A:$A,0)),"⚠ kode tidak ditemukan")) | L10: =IF(C10="","",IFERROR(INDEX('07_Unit'!$D:$D,MATCH(C10,'07_Unit'!$A:$A,0)),"⚠ kode tidak ditemukan")) | M10: =IF(OR(D10="",E10=""),0,D10*E10)
J11: =IF(C11="","",IFERROR(INDEX('07_Unit'!$B:$B,MATCH(C11,'07_Unit'!$A:$A,0)),"⚠ kode tidak ditemukan")) | K11: =IF(C11="","",IFERROR(INDEX('07_Unit'!$C:$C,MATCH(C11,'07_Unit'!$A:$A,0)),"⚠ kode tidak ditemukan")) | L11: =IF(C11="","",IFERROR(INDEX('07_Unit'!$D:$D,MATCH(C11,'07_Unit'!$A:$A,0)),"⚠ kode tidak ditemukan")) | M11: =IF(OR(D11="",E11=""),0,D11*E11)
J12: =IF(C12="","",IFERROR(INDEX('07_Unit'!$B:$B,MATCH(C12,'07_Unit'!$A:$A,0)),"⚠ kode tidak ditemukan")) | K12: =IF(C12="","",IFERROR(INDEX('07_Unit'!$C:$C,MATCH(C12,'07_Unit'!$A:$A,0)),"⚠ kode tidak ditemukan")) | L12: =IF(C12="","",IFERROR(INDEX('07_Unit'!$D:$D,MATCH(C12,'07_Unit'!$A:$A,0)),"⚠ kode tidak ditemukan")) | M12: =IF(OR(D12="",E12=""),0,D12*E12)
J13: =IF(C13="","",IFERROR(INDEX('07_Unit'!$B:$B,MATCH(C13,'07_Unit'!$A:$A,0)),"⚠ kode tidak ditemukan")) | K13: =IF(C13="","",IFERROR(INDEX('07_Unit'!$C:$C,MATCH(C13,'07_Unit'!$A:$A,0)),"⚠ kode tidak ditemukan")) | L13: =IF(C13="","",IFERROR(INDEX('07_Unit'!$D:$D,MATCH(C13,'07_Unit'!$A:$A,0)),"⚠ kode tidak ditemukan")) | M13: =IF(OR(D13="",E13=""),0,D13*E13)
J14: =IF(C14="","",IFERROR(INDEX('07_Unit'!$B:$B,MATCH(C14,'07_Unit'!$A:$A,0)),"⚠ kode tidak ditemukan")) | K14: =IF(C14="","",IFERROR(INDEX('07_Unit'!$C:$C,MATCH(C14,'07_Unit'!$A:$A,0)),"⚠ kode tidak ditemukan")) | L14: =IF(C14="","",IFERROR(INDEX('07_Unit'!$D:$D,MATCH(C14,'07_Unit'!$A:$A,0)),"⚠ kode tidak ditemukan")) | M14: =IF(OR(D14="",E14=""),0,D14*E14)
J15: =IF(C15="","",IFERROR(INDEX('07_Unit'!$B:$B,MATCH(C15,'07_Unit'!$A:$A,0)),"⚠ kode tidak ditemukan")) | K15: =IF(C15="","",IFERROR(INDEX('07_Unit'!$C:$C,MATCH(C15,'07_Unit'!$A:$A,0)),"⚠ kode tidak ditemukan")) | L15: =IF(C15="","",IFERROR(INDEX('07_Unit'!$D:$D,MATCH(C15,'07_Unit'!$A:$A,0)),"⚠ kode tidak ditemukan")) | M15: =IF(OR(D15="",E15=""),0,D15*E15)
J16: =IF(C16="","",IFERROR(INDEX('07_Unit'!$B:$B,MATCH(C16,'07_Unit'!$A:$A,0)),"⚠ kode tidak ditemukan")) | K16: =IF(C16="","",IFERROR(INDEX('07_Unit'!$C:$C,MATCH(C16,'07_Unit'!$A:$A,0)),"⚠ kode tidak ditemukan")) | L16: =IF(C16="","",IFERROR(INDEX('07_Unit'!$D:$D,MATCH(C16,'07_Unit'!$A:$A,0)),"⚠ kode tidak ditemukan")) | M16: =IF(OR(D16="",E16=""),0,D16*E16)
... J404: =IF(C404="","",IFERROR(INDEX('07_Unit'!$B:$B,MATCH(C404,'07_Unit'!$A:$A,0)),"⚠ kode tidak ditemukan")) | K404: =IF(C404="","",IFERROR(INDEX('07_Unit'!$C:$C,MATCH(C404,'07_Unit'!$A:$A,0)),"⚠ kode tidak ditemukan")) | L404: =IF(C404="","",IFERROR(INDEX('07_Unit'!$D:$D,MATCH(C404,'07_Unit'!$A:$A,0)),"⚠ kode tidak ditemukan")) | M404: =IF(OR(D404="",E404=""),0,D404*E404)

Sheet 15_Aset_Alat
A1: 15 · Aset / Alat per Ruangan
A2: SELURUH alat medis & non-medis, satu baris per jenis alat. "Tetap" = jumlah sudah total; "Per satuan" = jumlah dikalikan Jumlah Unit ruangan (mis. per tempat tidur).
A3: WAJIB DIISI | B3: WAJIB DIISI | C3: WAJIB DIISI | D3: WAJIB DIISI | E3: WAJIB DIISI | F3: WAJIB DIISI | G3: OPSIONAL | H3: OPSIONAL | I3: OTOMATIS | J3: OTOMATIS | K3: OTOMATIS | L3: OTOMATIS
A4: Kode Ruang | B4: Kode Kategori | C4: Nama Alat | D4: Jumlah | E4: Basis Jumlah | F4: Harga Satuan (Rp) | G4: Nilai Sisa (Rp) | H4: Sumber Data | I4: Nama Ruangan | J4: Kategori Aset | K4: Jenis (Medis/Non-Medis) | L4: Nilai Perolehan (Rp)
I5: =IF(A5="","",IFERROR(INDEX('14_Ruang'!$B:$B,MATCH(A5,'14_Ruang'!$A:$A,0)),"⚠ kode tidak ditemukan")) | J5: =IF(B5="","",IFERROR(INDEX('03_Kategori_Aset'!$B:$B,MATCH(B5,'03_Kategori_Aset'!$A:$A,0)),"⚠ kode tidak ditemukan")) | K5: =IF(B5="","",IFERROR(INDEX('03_Kategori_Aset'!$C:$C,MATCH(B5,'03_Kategori_Aset'!$A:$A,0)),"⚠ kode tidak ditemukan")) | L5: =IF(OR(A5="",D5="",F5=""),0,D5*IF(E5="Per satuan",IFERROR(INDEX('14_Ruang'!$E:$E,MATCH(A5,'14_Ruang'!$A:$A,0)),0),1)*F5)
I6: =IF(A6="","",IFERROR(INDEX('14_Ruang'!$B:$B,MATCH(A6,'14_Ruang'!$A:$A,0)),"⚠ kode tidak ditemukan")) | J6: =IF(B6="","",IFERROR(INDEX('03_Kategori_Aset'!$B:$B,MATCH(B6,'03_Kategori_Aset'!$A:$A,0)),"⚠ kode tidak ditemukan")) | K6: =IF(B6="","",IFERROR(INDEX('03_Kategori_Aset'!$C:$C,MATCH(B6,'03_Kategori_Aset'!$A:$A,0)),"⚠ kode tidak ditemukan")) | L6: =IF(OR(A6="",D6="",F6=""),0,D6*IF(E6="Per satuan",IFERROR(INDEX('14_Ruang'!$E:$E,MATCH(A6,'14_Ruang'!$A:$A,0)),0),1)*F6)
I7: =IF(A7="","",IFERROR(INDEX('14_Ruang'!$B:$B,MATCH(A7,'14_Ruang'!$A:$A,0)),"⚠ kode tidak ditemukan")) | J7: =IF(B7="","",IFERROR(INDEX('03_Kategori_Aset'!$B:$B,MATCH(B7,'03_Kategori_Aset'!$A:$A,0)),"⚠ kode tidak ditemukan")) | K7: =IF(B7="","",IFERROR(INDEX('03_Kategori_Aset'!$C:$C,MATCH(B7,'03_Kategori_Aset'!$A:$A,0)),"⚠ kode tidak ditemukan")) | L7: =IF(OR(A7="",D7="",F7=""),0,D7*IF(E7="Per satuan",IFERROR(INDEX('14_Ruang'!$E:$E,MATCH(A7,'14_Ruang'!$A:$A,0)),0),1)*F7)
I8: =IF(A8="","",IFERROR(INDEX('14_Ruang'!$B:$B,MATCH(A8,'14_Ruang'!$A:$A,0)),"⚠ kode tidak ditemukan")) | J8: =IF(B8="","",IFERROR(INDEX('03_Kategori_Aset'!$B:$B,MATCH(B8,'03_Kategori_Aset'!$A:$A,0)),"⚠ kode tidak ditemukan")) | K8: =IF(B8="","",IFERROR(INDEX('03_Kategori_Aset'!$C:$C,MATCH(B8,'03_Kategori_Aset'!$A:$A,0)),"⚠ kode tidak ditemukan")) | L8: =IF(OR(A8="",D8="",F8=""),0,D8*IF(E8="Per satuan",IFERROR(INDEX('14_Ruang'!$E:$E,MATCH(A8,'14_Ruang'!$A:$A,0)),0),1)*F8)
I9: =IF(A9="","",IFERROR(INDEX('14_Ruang'!$B:$B,MATCH(A9,'14_Ruang'!$A:$A,0)),"⚠ kode tidak ditemukan")) | J9: =IF(B9="","",IFERROR(INDEX('03_Kategori_Aset'!$B:$B,MATCH(B9,'03_Kategori_Aset'!$A:$A,0)),"⚠ kode tidak ditemukan")) | K9: =IF(B9="","",IFERROR(INDEX('03_Kategori_Aset'!$C:$C,MATCH(B9,'03_Kategori_Aset'!$A:$A,0)),"⚠ kode tidak ditemukan")) | L9: =IF(OR(A9="",D9="",F9=""),0,D9*IF(E9="Per satuan",IFERROR(INDEX('14_Ruang'!$E:$E,MATCH(A9,'14_Ruang'!$A:$A,0)),0),1)*F9)
I10: =IF(A10="","",IFERROR(INDEX('14_Ruang'!$B:$B,MATCH(A10,'14_Ruang'!$A:$A,0)),"⚠ kode tidak ditemukan")) | J10: =IF(B10="","",IFERROR(INDEX('03_Kategori_Aset'!$B:$B,MATCH(B10,'03_Kategori_Aset'!$A:$A,0)),"⚠ kode tidak ditemukan")) | K10: =IF(B10="","",IFERROR(INDEX('03_Kategori_Aset'!$C:$C,MATCH(B10,'03_Kategori_Aset'!$A:$A,0)),"⚠ kode tidak ditemukan")) | L10: =IF(OR(A10="",D10="",F10=""),0,D10*IF(E10="Per satuan",IFERROR(INDEX('14_Ruang'!$E:$E,MATCH(A10,'14_Ruang'!$A:$A,0)),0),1)*F10)
I11: =IF(A11="","",IFERROR(INDEX('14_Ruang'!$B:$B,MATCH(A11,'14_Ruang'!$A:$A,0)),"⚠ kode tidak ditemukan")) | J11: =IF(B11="","",IFERROR(INDEX('03_Kategori_Aset'!$B:$B,MATCH(B11,'03_Kategori_Aset'!$A:$A,0)),"⚠ kode tidak ditemukan")) | K11: =IF(B11="","",IFERROR(INDEX('03_Kategori_Aset'!$C:$C,MATCH(B11,'03_Kategori_Aset'!$A:$A,0)),"⚠ kode tidak ditemukan")) | L11: =IF(OR(A11="",D11="",F11=""),0,D11*IF(E11="Per satuan",IFERROR(INDEX('14_Ruang'!$E:$E,MATCH(A11,'14_Ruang'!$A:$A,0)),0),1)*F11)
I12: =IF(A12="","",IFERROR(INDEX('14_Ruang'!$B:$B,MATCH(A12,'14_Ruang'!$A:$A,0)),"⚠ kode tidak ditemukan")) | J12: =IF(B12="","",IFERROR(INDEX('03_Kategori_Aset'!$B:$B,MATCH(B12,'03_Kategori_Aset'!$A:$A,0)),"⚠ kode tidak ditemukan")) | K12: =IF(B12="","",IFERROR(INDEX('03_Kategori_Aset'!$C:$C,MATCH(B12,'03_Kategori_Aset'!$A:$A,0)),"⚠ kode tidak ditemukan")) | L12: =IF(OR(A12="",D12="",F12=""),0,D12*IF(E12="Per satuan",IFERROR(INDEX('14_Ruang'!$E:$E,MATCH(A12,'14_Ruang'!$A:$A,0)),0),1)*F12)
